<?xml version='1.0' encoding='us-ascii'?>
<robot name="e0509_with_gripper">
  <material name="black">
    <color rgba="0.0 0.0 0.0 1.0" />
  </material>
  <material name="white">
    <color rgba="1.0 1.0 1.0 1.0" />
  </material>
  <material name="orange">
    <color rgba="1.0 0.4 0.0 1.0" />
  </material>
  <material name="dr_gray">
    <color rgba="0.490 0.490 0.486 1.0" />
  </material>
  <material name="dr_white">
    <color rgba="0.941 0.941 0.941 1.0" />
  </material>
  <material name="dr_blue">
    <color rgba="0 0 0.15 1" />
  </material>
  <link name="base_link">
    <inertial>
      <mass value="1.803" />
      <origin xyz="2.7e-05   -0.002651    0.035122" />
      <inertia ixx="0.010608" ixy="1.7706e-06" ixz="6.6982e-06" iyy="0.0092656" iyz="-4.7833e-05" izz="0.0092125" />
    </inertial>
    <collision>
      <origin rpy="0 0 0" xyz="0 0 0" />
      <geometry>
        <mesh filename="package://dsr_description2/meshes/e0509_collision/E0509_0_0.dae" scale="0.001 0.001 0.001" />
      </geometry>
      <material name="dr_white" />
    </collision>
    <visual>
      <origin rpy="0 0 0" xyz="0 0 0" />
      <geometry>
        <mesh filename="package://dsr_description2/meshes/e0509_white/E0509_0_0.dae" scale="0.001 0.001 0.001" />
      </geometry>
      <material name="dr_white" />
    </visual>
  </link>
  
  <joint name="joint_1" type="revolute">
    <parent link="base_link" />
    <child link="link_1" />
    <origin rpy="0 0 0" xyz="0 0 0.2045" />
    <axis xyz="0 0 1" />
    <limit effort="194" lower="-6.283185307179586" upper="6.283185307179586" velocity="3.1416" />
    <dynamics friction="0" />
  </joint>
  <link name="link_1">
    <inertial>
      <mass value="5.75" />
      <origin xyz="1e-06    0.049633   -0.049635" />
      <inertia ixx="0.046214" ixy="1.4982e-05" ixz="1.281e-05" iyy="0.032573" iyz="-0.013997" izz="0.030999" />
    </inertial>
    <collision>
      <origin rpy="0 0 0" xyz="0 0 0" />
      <geometry>
        <mesh filename="package://dsr_description2/meshes/e0509_collision/E0509_1_1.dae" scale="0.001 0.001 0.001" />
      </geometry>
      <material name="dr_white" />
    </collision>
    <visual>
      <origin rpy="0 0 0" xyz="0 0 0" />
      <geometry>
        <mesh filename="package://dsr_description2/meshes/e0509_white/E0509_1_1.dae" scale="0.001 0.001 0.001" />
      </geometry>
      <material name="dr_white" />
    </visual>
    <collision>
      <origin rpy="0 0 0" xyz="0 0 0" />
      <geometry>
        <mesh filename="package://dsr_description2/meshes/e0509_collision/E0509_1_2.dae" scale="0.001 0.001 0.001" />
      </geometry>
      <material name="dr_white" />
    </collision>
    <visual>
      <origin rpy="0 0 0" xyz="0 0 0" />
      <geometry>
        <mesh filename="package://dsr_description2/meshes/e0509_white/E0509_1_2.dae" scale="0.001 0.001 0.001" />
      </geometry>
      <material name="dr_white" />
    </visual>
    <collision>
      <origin rpy="0 0 0" xyz="0 0 0" />
      <geometry>
        <mesh filename="package://dsr_description2/meshes/e0509_collision/E0509_1_3.dae" scale="0.001 0.001 0.001" />
      </geometry>
      <material name="dr_white" />
    </collision>
    <visual>
      <origin rpy="0 0 0" xyz="0 0 0" />
      <geometry>
        <mesh filename="package://dsr_description2/meshes/e0509_white/E0509_1_3.dae" scale="0.001 0.001 0.001" />
      </geometry>
      <material name="dr_white" />
    </visual>
    <collision>
      <origin rpy="0 0 0" xyz="0 0 0" />
      <geometry>
        <mesh filename="package://dsr_description2/meshes/e0509_collision/E0509_1_4.dae" scale="0.001 0.001 0.001" />
      </geometry>
      <material name="dr_white" />
    </collision>
    <visual>
      <origin rpy="0 0 0" xyz="0 0 0" />
      <geometry>
        <mesh filename="package://dsr_description2/meshes/e0509_white/E0509_1_4.dae" scale="0.001 0.001 0.001" />
      </geometry>
      <material name="dr_white" />
    </visual>
  </link>
  
  <joint name="joint_2" type="revolute">
    <parent link="link_1" />
    <child link="link_2" />
    <origin rpy="0 -1.5708 -1.5708" xyz="0 0 0" />
    <axis xyz="0 0 1" />
    <limit effort="194" lower="-1.6580627893946132" upper="1.6580627893946132" velocity="3.1416" />
    <dynamics friction="0" />
  </joint>
  <link name="link_2">
    <inertial>
      <mass value="3.461" />
      <origin xyz="0.18647 -1.1418e-17     0.17311" />
      <inertia ixx="0.012039" ixy="7.7771e-06" ixz="3.7559e-06" iyy="0.091203" iyz="3.1825e-06" izz="0.094721" />
    </inertial>
    <collision>
      <origin rpy="0 0 0" xyz="0 0 0" />
      <geometry>
        <mesh filename="package://dsr_description2/meshes/e0509_collision/E0509_2_1.dae" scale="0.001 0.001 0.001" />
      </geometry>
      <material name="dr_white" />
    </collision>
    <visual>
      <origin rpy="0 0 0" xyz="0 0 0" />
      <geometry>
        <mesh filename="package://dsr_description2/meshes/e0509_white/E0509_2_1.dae" scale="0.001 0.001 0.001" />
      </geometry>
      <material name="dr_white" />
    </visual>
    <collision>
      <origin rpy="0 0 0" xyz="0 0 0" />
      <geometry>
        <mesh filename="package://dsr_description2/meshes/e0509_collision/E0509_2_2.dae" scale="0.001 0.001 0.001" />
      </geometry>
      <material name="dr_white" />
    </collision>
    <visual>
      <origin rpy="0 0 0" xyz="0 0 0" />
      <geometry>
        <mesh filename="package://dsr_description2/meshes/e0509_white/E0509_2_2.dae" scale="0.001 0.001 0.001" />
      </geometry>
      <material name="dr_white" />
    </visual>
  </link>
  
  <joint name="joint_3" type="revolute">
    <parent link="link_2" />
    <child link="link_3" />
    <origin rpy="0 0 1.5708" xyz="0.373 0 0" />
    <axis xyz="0 0 1" />
    <limit effort="194" lower="-2.356194490192345" upper="2.356194490192345" velocity="3.1416" />
    <dynamics friction="0" />
  </joint>
  <link name="link_3">
    <inertial>
      <mass value="4.582" />
      <origin xyz="1.2e-05    -0.02919    0.062355" />
      <inertia ixx="0.032606" ixy="6.548e-06" ixz="-6.9939e-07" iyy="0.024211" iyz="-0.0079929" izz="0.019284" />
    </inertial>
    <collision>
      <origin rpy="0 0 0" xyz="0 0 0" />
      <geometry>
        <mesh filename="package://dsr_description2/meshes/e0509_collision/E0509_3_1.dae" scale="0.001 0.001 0.001" />
      </geometry>
      <material name="dr_white" />
    </collision>
    <visual>
      <origin rpy="0 0 0" xyz="0 0 0" />
      <geometry>
        <mesh filename="package://dsr_description2/meshes/e0509_white/E0509_3_1.dae" scale="0.001 0.001 0.001" />
      </geometry>
      <material name="dr_white" />
    </visual>
    <collision>
      <origin rpy="0 0 0" xyz="0 0 0" />
      <geometry>
        <mesh filename="package://dsr_description2/meshes/e0509_collision/E0509_3_2.dae" scale="0.001 0.001 0.001" />
      </geometry>
      <material name="dr_white" />
    </collision>
    <visual>
      <origin rpy="0 0 0" xyz="0 0 0" />
      <geometry>
        <mesh filename="package://dsr_description2/meshes/e0509_white/E0509_3_2.dae" scale="0.001 0.001 0.001" />
      </geometry>
      <material name="dr_white" />
    </visual>
  </link>
  
  <joint name="joint_4" type="revolute">
    <parent link="link_3" />
    <child link="link_4" />
    <origin rpy="1.5708 0 0" xyz="0 -0.373 0" />
    <axis xyz="0 0 1" />
    <limit effort="66" lower="-6.283185307179586" upper="6.283185307179586" velocity="3.927" />
    <dynamics friction="0" />
  </joint>
  <link name="link_4">
    <inertial>
      <mass value="2.207" />
      <origin xyz="4e-06    0.095573    -0.12813" />
      <inertia ixx="0.03547" ixy="8.0794e-06" ixz="7.9905e-06" iyy="0.030841" iyz="-0.011996" izz="0.019615" />
    </inertial>
    <collision>
      <origin rpy="0 0 0" xyz="0 0 0" />
      <geometry>
        <mesh filename="package://dsr_description2/meshes/e0509_collision/E0509_4_1.dae" scale="0.001 0.001 0.001" />
      </geometry>
      <material name="dr_white" />
    </collision>
    <visual>
      <origin rpy="0 0 0" xyz="0 0 0" />
      <geometry>
        <mesh filename="package://dsr_description2/meshes/e0509_white/E0509_4_1.dae" scale="0.001 0.001 0.001" />
      </geometry>
      <material name="dr_white" />
    </visual>
    <collision>
      <origin rpy="0 0 0" xyz="0 0 0" />
      <geometry>
        <mesh filename="package://dsr_description2/meshes/e0509_collision/E0509_4_2.dae" scale="0.001 0.001 0.001" />
      </geometry>
      <material name="dr_white" />
    </collision>
    <visual>
      <origin rpy="0 0 0" xyz="0 0 0" />
      <geometry>
        <mesh filename="package://dsr_description2/meshes/e0509_white/E0509_4_2.dae" scale="0.001 0.001 0.001" />
      </geometry>
      <material name="dr_white" />
    </visual>
  </link>
  
  <joint name="joint_5" type="revolute">
    <parent link="link_4" />
    <child link="link_5" />
    <origin rpy="-1.5708 0 0" xyz="0 0 0" />
    <axis xyz="0 0 1" />
    <limit effort="66" lower="-2.356194490192345" upper="2.356194490192345" velocity="3.927" />
    <dynamics friction="0" />
  </joint>
  <link name="link_5">
    <inertial>
      <mass value="3.545" />
      <origin xyz="-3e-06 -0.038009 0.043841" />
      <inertia ixx="0.023526" ixy="9.9368e-06" ixz="7.6673e-06" iyy="0.018415" iyz="-0.0059939" izz="0.014249" />
    </inertial>
    <collision>
      <origin rpy="0 0 0" xyz="0 0 0" />
      <geometry>
        <mesh filename="package://dsr_description2/meshes/e0509_collision/E0509_5_1.dae" scale="0.001 0.001 0.001" />
      </geometry>
      <material name="dr_white" />
    </collision>
    <visual>
      <origin rpy="0 0 0" xyz="0 0 0" />
      <geometry>
        <mesh filename="package://dsr_description2/meshes/e0509_white/E0509_5_1.dae" scale="0.001 0.001 0.001" />
      </geometry>
      <material name="dr_white" />
    </visual>
    <collision>
      <origin rpy="0 0 0" xyz="0 0 0" />
      <geometry>
        <mesh filename="package://dsr_description2/meshes/e0509_collision/E0509_5_2.dae" scale="0.001 0.001 0.001" />
      </geometry>
      <material name="dr_white" />
    </collision>
    <visual>
      <origin rpy="0 0 0" xyz="0 0 0" />
      <geometry>
        <mesh filename="package://dsr_description2/meshes/e0509_white/E0509_5_2.dae" scale="0.001 0.001 0.001" />
      </geometry>
      <material name="dr_white" />
    </visual>
  </link>
  
  <joint name="joint_6" type="revolute">
    <parent link="link_5" />
    <child link="link_6" />
    <origin rpy="1.5708 0 0" xyz="0 -0.1725 0" />
    <axis xyz="0 0 1" />
    <limit effort="66" lower="-6.283185307179586" upper="6.283185307179586" velocity="3.927" />
    <dynamics friction="0" />
  </joint>
  <link name="link_6">
    <inertial>
      <mass value="0.721" />
      <origin xyz="5.4e-05   -0.000114   -0.032091" />
      <inertia ixx="0.0048272" ixy="5.6302e-06" ixz="5.5274e-06" iyy="0.0046772" iyz="3.9598e-06" izz="0.0079424" />
    </inertial>
    <collision>
      <origin rpy="0 0 0" xyz="0 0 0" />
      <geometry>
        <mesh filename="package://dsr_description2/meshes/e0509_collision/E0509_6_1.dae" scale="0.001 0.001 0.001" />
      </geometry>
      <material name="dr_white" />
    </collision>
    <visual>
      <origin rpy="0 0 0" xyz="0 0 0" />
      <geometry>
        <mesh filename="package://dsr_description2/meshes/e0509_white/E0509_6_1.dae" scale="0.001 0.001 0.001" />
      </geometry>
      <material name="dr_white" />
    </visual>
  </link>
  
  <link name="world" />
  <joint name="world_fixed" type="fixed">
    <origin rpy="0 0 0" xyz="0 0 0" />
    <parent link="world" />
    <child link="base_link" />
  </joint>
  
  <link name="gripper_rh_p12_rn_base">
    <collision>
      <origin rpy="0 0 0" xyz="0 0 0" />
      <geometry>
        <mesh filename="package://rh_p12_rn_a_description/meshes/base.stl" scale="0.001 0.001 0.001" />
      </geometry>
    </collision>
    <visual>
      <origin rpy="0 0 0" xyz="0 0 0" />
      <geometry>
        <mesh filename="package://rh_p12_rn_a_description/meshes/base.stl" scale="0.001 0.001 0.001" />
      </geometry>
      <material name="grey">
        <color rgba="0.2 0.2 0.2 1" />
      </material>
    </visual>
    <inertial>
      <origin rpy="0 0 0" xyz="0.000 0.000 0.032" />
      <mass value="0.236" />
      <inertia ixx="0.000001" ixy="0.0" ixz="0.0" iyy="0.000001" iyz="0.0" izz="0.000001" />
    </inertial>
  </link>
  
  <joint name="gripper_rh_r1" type="revolute">
    <parent link="gripper_rh_p12_rn_base" />
    <child link="gripper_rh_p12_rn_r1" />
    <origin rpy="0 0 0" xyz="0.0 0.008 0.048" />
    <axis xyz="1 0 0" />
    <limit effort="1000" lower="-0.001" upper="1.101" velocity="6.5" />
    <dynamics damping="0.7" />
  </joint>
  
  <link name="gripper_rh_p12_rn_r1">
    <collision>
      <origin rpy="0 0 0" xyz="0 0 0" />
      <geometry>
        <mesh filename="package://rh_p12_rn_a_description/meshes/r1.stl" scale="0.001 0.001 0.001" />
      </geometry>
    </collision>
    <visual>
      <origin rpy="0 0 0" xyz="0 0 0" />
      <geometry>
        <mesh filename="package://rh_p12_rn_a_description/meshes/r1.stl" scale="0.001 0.001 0.001" />
      </geometry>
      <material name="grey">
        <color rgba="0.2 0.2 0.2 1" />
      </material>
    </visual>
    <inertial>
      <origin rpy="0 0 0" xyz="0.000 0.034 0.004" />
      <mass value="0.068" />
      <inertia ixx="0.000001" ixy="0.0" ixz="0.0" iyy="0.000001" iyz="0.0" izz="0.000001" />
    </inertial>
  </link>
  
  <joint name="gripper_rh_r2" type="revolute">
    <parent link="gripper_rh_p12_rn_r1" />
    <child link="gripper_rh_p12_rn_r2" />
    <origin rpy="0 0 0" xyz="0.0 0.0493634 0.0285" />
    <axis xyz="-1 0 0" />
    <limit effort="1000" lower="-0.001" upper="1.101" velocity="6.5" />
    <dynamics damping="0.7" />
    <mimic joint="gripper_rh_r1" multiplier="1" />
  </joint>
  
  <link name="gripper_rh_p12_rn_r2">
    <collision>
      <origin rpy="0 0 0" xyz="0 0 0" />
      <geometry>
        <mesh filename="package://rh_p12_rn_a_description/meshes/r2.stl" scale="0.001 0.001 0.001" />
      </geometry>
    </collision>
    <visual>
      <origin rpy="0 0 0" xyz="0 0 0" />
      <geometry>
        <mesh filename="package://rh_p12_rn_a_description/meshes/r2.stl" scale="0.001 0.001 0.001" />
      </geometry>
      <material name="grey">
        <color rgba="0.2 0.2 0.2 1" />
      </material>
    </visual>
    <inertial>
      <origin rpy="0 0 0" xyz="0.000 0.006 0.011" />
      <mass value="0.022" />
      <inertia ixx="0.000001" ixy="0.0" ixz="0.0" iyy="0.000001" iyz="0.0" izz="0.000001" />
    </inertial>
  </link>
  
  <joint name="gripper_rh_l1" type="revolute">
    <parent link="gripper_rh_p12_rn_base" />
    <child link="gripper_rh_p12_rn_l1" />
    <origin rpy="0 0 0" xyz="0.0 -0.008 0.048" />
    <axis xyz="-1 0 0" />
    <limit effort="1000" lower="-0.001" upper="1.101" velocity="6.5" />
    <dynamics damping="0.7" />
    <mimic joint="gripper_rh_r1" multiplier="1" />
  </joint>
  
  <link name="gripper_rh_p12_rn_l1">
    <collision>
      <origin rpy="0 0 0" xyz="0 0 0" />
      <geometry>
        <mesh filename="package://rh_p12_rn_a_description/meshes/l1.stl" scale="0.001 0.001 0.001" />
      </geometry>
    </collision>
    <visual>
      <origin rpy="0 0 0" xyz="0 0 0" />
      <geometry>
        <mesh filename="package://rh_p12_rn_a_description/meshes/l1.stl" scale="0.001 0.001 0.001" />
      </geometry>
      <material name="grey">
        <color rgba="0.2 0.2 0.2 1" />
      </material>
    </visual>
    <inertial>
      <origin rpy="0 0 0" xyz="0.000 -0.034 0.004" />
      <mass value="0.068" />
      <inertia ixx="0.000001" ixy="0.0" ixz="0.0" iyy="0.000001" iyz="0.0" izz="0.000001" />
    </inertial>
  </link>
  
  <joint name="gripper_rh_l2" type="revolute">
    <parent link="gripper_rh_p12_rn_l1" />
    <child link="gripper_rh_p12_rn_l2" />
    <origin rpy="0 0 0" xyz="0.0 -0.0493634 0.0285" />
    <axis xyz="1 0 0" />
    <limit effort="1000" lower="-0.001" upper="1.101" velocity="6.5" />
    <dynamics damping="0.7" />
    <mimic joint="gripper_rh_r1" multiplier="1" />
  </joint>
  
  <link name="gripper_rh_p12_rn_l2">
    <collision>
      <origin rpy="0 0 0" xyz="0 0 0" />
      <geometry>
        <mesh filename="package://rh_p12_rn_a_description/meshes/l2.stl" scale="0.001 0.001 0.001" />
      </geometry>
    </collision>
    <visual>
      <origin rpy="0 0 0" xyz="0 0 0" />
      <geometry>
        <mesh filename="package://rh_p12_rn_a_description/meshes/l2.stl" scale="0.001 0.001 0.001" />
      </geometry>
      <material name="grey">
        <color rgba="0.2 0.2 0.2 1" />
      </material>
    </visual>
    <inertial>
      <origin rpy="0 0 0" xyz="0.000 -0.006 0.011" />
      <mass value="0.022" />
      <inertia ixx="0.000001" ixy="0.0" ixz="0.0" iyy="0.000001" iyz="0.0" izz="0.000001" />
    </inertial>
  </link>
  
  <joint name="gripper_attach_joint" type="fixed">
    <origin rpy="0 0 1.5708" xyz="0 0.0 0.0" />
    <parent link="link_6" />
    <child link="gripper_rh_p12_rn_base" />
  </joint>
  </robot>